{"publishedDate": "2025-07-28T18:42Z", "lastModifiedDate": "2025-08-07T20:16Z", "cve": {"data_type": "CVE", "data_format": "MITRE", "data_version": "5.1", "CVE_data_meta": {"ID": "CVE-2025-8194", "ASSIGNER": "PSF"}, "description": {"description_data": [{"lang": "en", "supportingMedia": [{"base64": false, "type": "text/html", "value": "There is a defect in the CPython \u201ctarfile\u201d module affecting the \u201cTarFile\u201d extraction and entry enumeration APIs. The tar implementation would process tar archives with negative offsets without error, resulting in an infinite loop and deadlock during the parsing of maliciously crafted tar archives. <br><br>This vulnerability can be mitigated by including the following patch after importing the \u201ctarfile\u201d module:&nbsp;<a target=\"_blank\" rel=\"nofollow\" href=\"https://gist.github.com/sethmlarson/1716ac5b82b73dbcbf23ad2eff8b33e1\">https://gist.github.com/sethmlarson/1716ac5b82b73dbcbf23ad2eff8b33e1</a><div><br></div><br>"}], "value": "There is a defect in the CPython \u201ctarfile\u201d module affecting the \u201cTarFile\u201d extraction and entry enumeration APIs. The tar implementation would process tar archives with negative offsets without error, resulting in an infinite loop and deadlock during the parsing of maliciously crafted tar archives. \n\nThis vulnerability can be mitigated by including the following patch after importing the \u201ctarfile\u201d module:\u00a0 https://gist.github.com/sethmlarson/1716ac5b82b73dbcbf23ad2eff8b33e1"}]}, "references": {"reference_data": [{"tags": ["issue-tracking"], "url": "https://github.com/python/cpython/issues/130577"}, {"tags": ["patch"], "url": "https://github.com/python/cpython/pull/137027"}, {"tags": ["vendor-advisory"], "url": "https://mail.python.org/archives/list/security-announce@python.org/thread/ZULLF3IZ726XP5EY7XJ7YIN3K5MDYR2D/"}, {"tags": ["patch"], "url": "https://github.com/python/cpython/commit/7040aa54f14676938970e10c5f74ea93cd56aa38"}, {"tags": ["patch"], "url": "https://github.com/python/cpython/commit/cdae923ffe187d6ef916c0f665a31249619193fe"}, {"tags": ["mitigation"], "url": "https://gist.github.com/sethmlarson/1716ac5b82b73dbcbf23ad2eff8b33e1"}, {"tags": ["patch"], "url": "https://github.com/python/cpython/commit/c9d9f78feb1467e73fd29356c040bde1c104f29f"}, {"tags": ["patch"], "url": "https://github.com/python/cpython/commit/fbc2a0ca9ac8aff6887f8ddf79b87b4510277227"}]}, "problemtype": {"problemtype_data": [{"description": [{"lang": "en", "value": "CWE-835"}]}]}}, "impact": {"baseMetricV3": {"cvssV3": {"cvssV3_1": {"attackComplexity": "LOW", "attackVector": "NETWORK", "availabilityImpact": "HIGH", "baseScore": 7.5, "baseSeverity": "HIGH", "confidentialityImpact": "NONE", "integrityImpact": "NONE", "privilegesRequired": "NONE", "scope": "UNCHANGED", "userInteraction": "NONE", "vectorString": "CVSS:3.1/AV:N/AC:L/PR:N/UI:N/S:U/C:N/I:N/A:H", "version": "3.1"}, "format": "CVSS", "scenarios": [{"lang": "en", "value": "GENERAL"}]}}}, "configurations": {"CVE_data_version": "4.0", "nodes": [{"operator": "OR", "children": [], "cpe_match": [{"vulnerable": true, "cpe23Uri": "cpe:2.3:a:python software foundation:cpython:3.14.0:*:*:*:*:*:*:*", "cpe_name": []}, {"vulnerable": true, "cpe23Uri": "cpe:2.3:a:python software foundation:cpython:3.13.6:*:*:*:*:*:*:*", "cpe_name": []}]}]}}