{"publishedDate": "2025-02-14T16:18Z", "lastModifiedDate": "2025-02-14T19:02Z", "cve": {"data_type": "CVE", "data_format": "MITRE", "data_version": "5.1", "CVE_data_meta": {"ID": "CVE-2024-3220", "ASSIGNER": "PSF"}, "description": {"description_data": [{"lang": "en", "supportingMedia": [{"base64": false, "type": "text/html", "value": "There is a defect in the CPython standard library module \u201cmimetypes\u201d where on Windows the default list of known file locations are writable meaning other users can create invalid files to cause MemoryError to be raised on Python runtime startup or have file extensions be interpreted as the incorrect file type.<br><br>This defect is caused by the default locations of Linux and macOS platforms (such as \u201c/etc/mime.types\u201d) also being used on Windows, where they are user-writable locations (\u201cC:\\etc\\mime.types\u201d).<br><br>To work-around this issue a user can call mimetypes.init() with an empty list (\u201c[]\u201d) on Windows platforms to avoid using the default list of known file locations."}], "value": "There is a defect in the CPython standard library module \u201cmimetypes\u201d where on Windows the default list of known file locations are writable meaning other users can create invalid files to cause MemoryError to be raised on Python runtime startup or have file extensions be interpreted as the incorrect file type.\n\nThis defect is caused by the default locations of Linux and macOS platforms (such as \u201c/etc/mime.types\u201d) also being used on Windows, where they are user-writable locations (\u201cC:\\etc\\mime.types\u201d).\n\nTo work-around this issue a user can call mimetypes.init() with an empty list (\u201c[]\u201d) on Windows platforms to avoid using the default list of known file locations."}]}, "references": {"reference_data": [{"tags": ["vendor-advisory"], "url": "https://mail.python.org/archives/list/security-announce@python.org/thread/CDXW34ND2LSAOYAR5N6UNONP4ZBX4D6R/"}]}, "problemtype": {"problemtype_data": [{"description": [{"lang": "en", "value": "CWE-426"}]}]}}, "impact": {"baseMetricV4": {"cvssV4": {"cvssV4_0": {"Automatable": "NOT_DEFINED", "Recovery": "NOT_DEFINED", "Safety": "NOT_DEFINED", "attackComplexity": "LOW", "attackRequirements": "PRESENT", "attackVector": "NETWORK", "baseScore": 2.3, "baseSeverity": "LOW", "privilegesRequired": "LOW", "providerUrgency": "NOT_DEFINED", "subAvailabilityImpact": "NONE", "subConfidentialityImpact": "NONE", "subIntegrityImpact": "NONE", "userInteraction": "NONE", "valueDensity": "NOT_DEFINED", "vectorString": "CVSS:4.0/AV:N/AC:L/AT:P/PR:L/UI:N/VC:N/VI:L/VA:L/SC:N/SI:N/SA:N", "version": "4.0", "vulnAvailabilityImpact": "LOW", "vulnConfidentialityImpact": "NONE", "vulnIntegrityImpact": "LOW", "vulnerabilityResponseEffort": "NOT_DEFINED"}, "format": "CVSS", "scenarios": [{"lang": "en", "value": "GENERAL"}]}}}, "configurations": {"CVE_data_version": "4.0", "nodes": [{"operator": "OR", "children": [], "cpe_match": [{"vulnerable": true, "cpe23Uri": "cpe:2.3:a:python software foundation:cpython:3.14.0:*:*:*:*:*:*:*", "cpe_name": []}]}]}}